پاسخ کوتاه این است: **نه، آنها برابر نیستند**:

تفاوت این است که اگر خطایی در «f1» رخ دهد، در اینجا توسط «.catch» مدیریت می‌شود:

```js run
promise
  .then(f1)
  .catch(f2);
```

اما اینجا نه:  

```js run
promise
  .then(f1, f2);
```

این به این دلیل است که خطایی به زنجیره منتقل می شود و در قطعه کد دوم هیچ زنجیره ای زیر 'f1' وجود ندارد.

به عبارت دیگر، سپس نتایج/خطاها را به .then/catch بعدی منتقل می کند. بنابراین در مثال اول، یک مشکل در زیر وجود دارد، و در مثال دوم وجود ندارد، بنابراین خطا کنترل نشده است.
